Workbook

Sheet CROQUI MODERNIZAÇÃO
B26: POSTE | H26: ENDEREÇO | P26: PTRO
P32: LOCALIDADE / CIDADE
B33: CAIXA DE EMENDA
B41: INFORMAÇÕES DA OR DE FIBRA
B42: OR / OT N° | G42: OBSERVAÇÕES | L42: EXECUTANTE
B43: OR / OT N° | D43: UF | E43: 98
B45: CABO | D45: DDD | E45: MA
B47: PRIMARIA | D47: SS
B49: DESCRIÇÃO SERVIÇO
B51: CAUSA
B53: OBRA | G53: TA
B54: TRATATIVAS | L54: MATERIAIS
L55: NET | M55: ITEM | T55: QTDE
M56: PROTETOR EMENDA
M57: CONJUNTO DE EMENDA
M58: PONTO DE TERMINAÇÃO (PTRO)
M59: CABO DE 48 F.O
M60: CABO DE 36 F.O
M61: CABO DE 24 F.O
M62: CABO DE 12 F.O
M63: CABO DE 06 F.O
M64: CABO DE 04 F.O
M65: CABO DE 72 F.O

Sheet CAPA
C1: ORDEM DE REDE | E1: Escritório | F1: Localidade | G1: CT
E2: RP | F2: 11529 | G2: LG
E3: Data:
E5: 43024
C7: Fibra Óptica | E7: Contratada:
C8: Manutenção | E8: Tel Telecomunicações Ltda.
E10: nº Contrato: 4100001314OP
C12: FH 01 #3 SS03 | E12: FTTX | G12: Nº OR SGCI
G13: 17100010164
G15: PERÍODO DE MEDIÇÃO
E16: ATA
H19: ATIVIDADE | I19: Carteira
E20: MO PONTOS | F20: 14.96 | I20: Execução
A22: CUSTOS | C22: Mão-de-Obra | F22: Custo MO | I22: Total
C23: Lfo | F23: 75.3 | G23: =[1]MEDIÇÃO!D82 -> #REF! | I23: =G23*F23 -> #REF!
C24: Cfo | F24: 199.88 | G24: =[1]MEDIÇÃO!D83 -> #REF! | I24: =G24*F24 -> #REF!
C25: G | F25: 81.06 | G25: =[1]MEDIÇÃO!D84 -> #REF! | I25: =G25*F25 -> #REF!
C26: P | F26: 67.35 | G26: =[1]MEDIÇÃO!D85 -> #REF! | I26: =G26*F26 -> #REF!
F29: Total R$ (MO) | I29: =SUM(I23:I28) -> #REF!
A30: ANDERSON JULIAN ESTEVÃO | F30: Total R$ (Mat) | I30: =[1]MEDIÇÃO!M83 -> #REF!
A31: Responsável Fibra Óptica Tel | F31: CUSTO TOTAL | I31: =SUM(I29:I30) -> #REF!
A33: ENDEREÇO
A34: R. JOSE LUIZ NUNES FL
A38: DESCRIÇÃO DAS ATIVIDADES // CAUSA // MOTIVO // URGÊNCIA
A39: POU FIBRA FTTH- TROCA DE CAIXA RARE
A40: FTTH_11529LG_03-F#43_01
A44: Informações passadas por: RE: | H44: ASS
A45: Informações passadas para: | H45: ASS
A46: Coordenacao Tel ciente: | H46: ASS
A47: Gestor Telefonica Ciente: RE: | D47: João Ricardo Felisberto | H47: ASS
A49: INSPEÇÃO
A50: Observações: | F50: INSPECIONADO | H50: NÃO INSPECIONADO
A53: AMAURI VACCHI PASSOS | F53: REINALDO RODRIGUES MARQUES
A55: GESTÃO - | F55: GERÊNCIA DE MANUTENÇÃO E OPERAÇÃO DE REDE
A59: ADALBERTO BERTELI JUNIOR
A60: ALBERTO MIGUEL CORTEZ
A61: ANTONIO CLARET RIBEIRO
A62: AMAURI VACCHI PASSOS
A63: GLAUCO ZAGO AQUINO OLIVEIRA
A64: MAURO RODRIGUES MOREIRA

Sheet RELATORIO MEDIÇÃO
A1: RELATORIO DE MEDIÇÃO | G1: REGIÃO
G2: RP
A3: SGCI | G3: Data Emissão:
A4: CÓDIGO | B4: PT | C4: TOT. | D4: L / C | E4: QT | F4: DESCRIÇÃO DA ATIVIDADE | I4: QTD
A5: 290033 | B5: =IF(A5=0,"",VLOOKUP(A5,'[1]CÓDIGO DE PONTOS'!$A$5:$D$998,4,0)) -> #N/A | C5: =E5*B5 -> #N/A | D5: =IF(A5=0,"",VLOOKUP(A5,'[1]CÓDIGO DE PONTOS'!$A$5:$C$998,3,0)) -> #N/A | E5: =I5 -> 0 | F5: =IF(A5=0,"",VLOOKUP(A5,'[1]CÓDIGO DE PONTOS'!$A$5:$B$998,2,0)) -> #N/A
A6: 290068 | B6: =IF(A6=0,"",VLOOKUP(A6,'[1]CÓDIGO DE PONTOS'!$A$5:$D$998,4,0)) -> #N/A | C6: =E6*B6 -> #N/A | D6: =IF(A6=0,"",VLOOKUP(A6,'[1]CÓDIGO DE PONTOS'!$A$5:$C$998,3,0)) -> #N/A | E6: =I6 -> 0 | F6: =IF(A6=0,"",VLOOKUP(A6,'[1]CÓDIGO DE PONTOS'!$A$5:$B$998,2,0)) -> #N/A
A7: 290106 | B7: =IF(A7=0,"",VLOOKUP(A7,'[1]CÓDIGO DE PONTOS'!$A$5:$D$998,4,0)) -> #N/A | C7: =E7*B7 -> #N/A | D7: =IF(A7=0,"",VLOOKUP(A7,'[1]CÓDIGO DE PONTOS'!$A$5:$C$998,3,0)) -> #N/A | E7: =I7 -> 0 | F7: =IF(A7=0,"",VLOOKUP(A7,'[1]CÓDIGO DE PONTOS'!$A$5:$B$998,2,0)) -> #N/A
A8: 290114 | B8: =IF(A8=0,"",VLOOKUP(A8,'[1]CÓDIGO DE PONTOS'!$A$5:$D$998,4,0)) -> #N/A | C8: =E8*B8 -> #N/A | D8: =IF(A8=0,"",VLOOKUP(A8,'[1]CÓDIGO DE PONTOS'!$A$5:$C$998,3,0)) -> #N/A | E8: =I8 -> 0 | F8: =IF(A8=0,"",VLOOKUP(A8,'[1]CÓDIGO DE PONTOS'!$A$5:$B$998,2,0)) -> #N/A
A9: 290149 | B9: =IF(A9=0,"",VLOOKUP(A9,'[1]CÓDIGO DE PONTOS'!$A$5:$D$998,4,0)) -> #N/A | C9: =E9*B9 -> #N/A | D9: =IF(A9=0,"",VLOOKUP(A9,'[1]CÓDIGO DE PONTOS'!$A$5:$C$998,3,0)) -> #N/A | E9: =I9 -> 0 | F9: =IF(A9=0,"",VLOOKUP(A9,'[1]CÓDIGO DE PONTOS'!$A$5:$B$998,2,0)) -> #N/A
A10: 290190 | B10: =IF(A10=0,"",VLOOKUP(A10,'[1]CÓDIGO DE PONTOS'!$A$5:$D$998,4,0)) -> #N/A | C10: =E10*B10 -> #N/A | D10: =IF(A10=0,"",VLOOKUP(A10,'[1]CÓDIGO DE PONTOS'!$A$5:$C$998,3,0)) -> #N/A | E10: =I10 -> 0 | F10: =IF(A10=0,"",VLOOKUP(A10,'[1]CÓDIGO DE PONTOS'!$A$5:$B$998,2,0)) -> #N/A
A11: 290211 | B11: =IF(A11=0,"",VLOOKUP(A11,'[1]CÓDIGO DE PONTOS'!$A$5:$D$998,4,0)) -> #N/A | C11: =E11*B11 -> #N/A | D11: =IF(A11=0,"",VLOOKUP(A11,'[1]CÓDIGO DE PONTOS'!$A$5:$C$998,3,0)) -> #N/A | E11: =I11 -> 0 | F11: =IF(A11=0,"",VLOOKUP(A11,'[1]CÓDIGO DE PONTOS'!$A$5:$B$998,2,0)) -> #N/A
A12: 290769 | B12: =IF(A12=0,"",VLOOKUP(A12,'[1]CÓDIGO DE PONTOS'!$A$5:$D$998,4,0)) -> #N/A | C12: =E12*B12 -> #N/A | D12: =IF(A12=0,"",VLOOKUP(A12,'[1]CÓDIGO DE PONTOS'!$A$5:$C$998,3,0)) -> #N/A | E12: =I12 -> 0 | F12: =IF(A12=0,"",VLOOKUP(A12,'[1]CÓDIGO DE PONTOS'!$A$5:$B$998,2,0)) -> #N/A
A13: 291579 | B13: =IF(A13=0,"",VLOOKUP(A13,'[1]CÓDIGO DE PONTOS'!$A$5:$D$998,4,0)) -> #N/A | C13: =E13*B13 -> #N/A | D13: =IF(A13=0,"",VLOOKUP(A13,'[1]CÓDIGO DE PONTOS'!$A$5:$C$998,3,0)) -> #N/A | E13: =I13 -> 0 | F13: =IF(A13=0,"",VLOOKUP(A13,'[1]CÓDIGO DE PONTOS'!$A$5:$B$998,2,0)) -> #N/A
A14: 291587 | B14: =IF(A14=0,"",VLOOKUP(A14,'[1]CÓDIGO DE PONTOS'!$A$5:$D$998,4,0)) -> #N/A | C14: =E14*B14 -> #N/A | D14: =IF(A14=0,"",VLOOKUP(A14,'[1]CÓDIGO DE PONTOS'!$A$5:$C$998,3,0)) -> #N/A | E14: =I14 -> 12 | F14: =IF(A14=0,"",VLOOKUP(A14,'[1]CÓDIGO DE PONTOS'!$A$5:$B$998,2,0)) -> #N/A | I14: 12
A15: 290262 | B15: =IF(A15=0,"",VLOOKUP(A15,'[1]CÓDIGO DE PONTOS'!$A$5:$D$998,4,0)) -> #N/A | C15: =E15*B15 -> #N/A | D15: =IF(A15=0,"",VLOOKUP(A15,'[1]CÓDIGO DE PONTOS'!$A$5:$C$998,3,0)) -> #N/A | E15: =I15 -> 0 | F15: =IF(A15=0,"",VLOOKUP(A15,'[1]CÓDIGO DE PONTOS'!$A$5:$B$998,2,0)) -> #N/A
A16: 290351 | B16: =IF(A16=0,"",VLOOKUP(A16,'[1]CÓDIGO DE PONTOS'!$A$5:$D$998,4,0)) -> #N/A | C16: =E16*B16 -> #N/A | D16: =IF(A16=0,"",VLOOKUP(A16,'[1]CÓDIGO DE PONTOS'!$A$5:$C$998,3,0)) -> #N/A | E16: =I16 -> 0 | F16: =IF(A16=0,"",VLOOKUP(A16,'[1]CÓDIGO DE PONTOS'!$A$5:$B$998,2,0)) -> #N/A
A17: 290050 | B17: =IF(A17=0,"",VLOOKUP(A17,'[1]CÓDIGO DE PONTOS'!$A$5:$D$998,4,0)) -> #N/A | C17: =E17*B17 -> #N/A | D17: =IF(A17=0,"",VLOOKUP(A17,'[1]CÓDIGO DE PONTOS'!$A$5:$C$998,3,0)) -> #N/A | E17: =I17 -> 0 | F17: =IF(A17=0,"",VLOOKUP(A17,'[1]CÓDIGO DE PONTOS'!$A$5:$B$998,2,0)) -> #N/A
A18: 290076 | B18: =IF(A18=0,"",VLOOKUP(A18,'[1]CÓDIGO DE PONTOS'!$A$5:$D$998,4,0)) -> #N/A | C18: =E18*B18 -> #N/A | D18: =IF(A18=0,"",VLOOKUP(A18,'[1]CÓDIGO DE PONTOS'!$A$5:$C$998,3,0)) -> #N/A | E18: =I18 -> 0 | F18: =IF(A18=0,"",VLOOKUP(A18,'[1]CÓDIGO DE PONTOS'!$A$5:$B$998,2,0)) -> #N/A
A19: 290131 | B19: =IF(A19=0,"",VLOOKUP(A19,'[1]CÓDIGO DE PONTOS'!$A$5:$D$998,4,0)) -> #N/A | C19: =E19*B19 -> #N/A | D19: =IF(A19=0,"",VLOOKUP(A19,'[1]CÓDIGO DE PONTOS'!$A$5:$C$998,3,0)) -> #N/A | E19: =I19 -> 0 | F19: =IF(A19=0,"",VLOOKUP(A19,'[1]CÓDIGO DE PONTOS'!$A$5:$B$998,2,0)) -> #N/A
A20: 290157 | B20: =IF(A20=0,"",VLOOKUP(A20,'[1]CÓDIGO DE PONTOS'!$A$5:$D$998,4,0)) -> #N/A | C20: =E20*B20 -> #N/A | D20: =IF(A20=0,"",VLOOKUP(A20,'[1]CÓDIGO DE PONTOS'!$A$5:$C$998,3,0)) -> #N/A | E20: =I20 -> 0 | F20: =IF(A20=0,"",VLOOKUP(A20,'[1]CÓDIGO DE PONTOS'!$A$5:$B$998,2,0)) -> #N/A
A21: 290203 | B21: =IF(A21=0,"",VLOOKUP(A21,'[1]CÓDIGO DE PONTOS'!$A$5:$D$998,4,0)) -> #N/A | C21: =E21*B21 -> #N/A | D21: =IF(A21=0,"",VLOOKUP(A21,'[1]CÓDIGO DE PONTOS'!$A$5:$C$998,3,0)) -> #N/A | E21: =I21 -> 0 | F21: =IF(A21=0,"",VLOOKUP(A21,'[1]CÓDIGO DE PONTOS'!$A$5:$B$998,2,0)) -> #N/A
A22: 290777 | B22: =IF(A22=0,"",VLOOKUP(A22,'[1]CÓDIGO DE PONTOS'!$A$5:$D$998,4,0)) -> #N/A | C22: =E22*B22 -> #N/A | D22: =IF(A22=0,"",VLOOKUP(A22,'[1]CÓDIGO DE PONTOS'!$A$5:$C$998,3,0)) -> #N/A | E22: =I22 -> 0 | F22: =IF(A22=0,"",VLOOKUP(A22,'[1]CÓDIGO DE PONTOS'!$A$5:$B$998,2,0)) -> #N/A
A23: 220558 | B23: =IF(A23=0,"",VLOOKUP(A23,'[1]CÓDIGO DE PONTOS'!$A$5:$D$998,4,0)) -> #N/A | C23: =E23*B23 -> #N/A | D23: =IF(A23=0,"",VLOOKUP(A23,'[1]CÓDIGO DE PONTOS'!$A$5:$C$998,3,0)) -> #N/A | E23: =I23 -> 0 | F23: =IF(A23=0,"",VLOOKUP(A23,'[1]CÓDIGO DE PONTOS'!$A$5:$B$998,2,0)) -> #N/A
A24: 221694 | B24: =IF(A24=0,"",VLOOKUP(A24,'[1]CÓDIGO DE PONTOS'!$A$5:$D$998,4,0)) -> #N/A | C24: =E24*B24 -> #N/A | D24: =IF(A24=0,"",VLOOKUP(A24,'[1]CÓDIGO DE PONTOS'!$A$5:$C$998,3,0)) -> #N/A | E24: =I24 -> 0 | F24: =IF(A24=0,"",VLOOKUP(A24,'[1]CÓDIGO DE PONTOS'!$A$5:$B$998,2,0)) -> #N/A
A25: 221864 | B25: =IF(A25=0,"",VLOOKUP(A25,'[1]CÓDIGO DE PONTOS'!$A$5:$D$998,4,0)) -> #N/A | D25: =IF(A25=0,"",VLOOKUP(A25,'[1]CÓDIGO DE PONTOS'!$A$5:$C$998,3,0)) -> #N/A | E25: =I25 -> 0 | F25: =IF(A25=0,"",VLOOKUP(A25,'[1]CÓDIGO DE PONTOS'!$A$5:$B$998,2,0)) -> #N/A
A26: 222569 | B26: =IF(A26=0,"",VLOOKUP(A26,'[1]CÓDIGO DE PONTOS'!$A$5:$D$998,4,0)) -> #N/A | C26: =E26*B26 -> #N/A | D26: =IF(A26=0,"",VLOOKUP(A26,'[1]CÓDIGO DE PONTOS'!$A$5:$C$998,3,0)) -> #N/A | E26: =I26 -> 0 | F26: =IF(A26=0,"",VLOOKUP(A26,'[1]CÓDIGO DE PONTOS'!$A$5:$B$998,2,0)) -> #N/A
A27: 221767 | B27: =IF(A27=0,"",VLOOKUP(A27,'[1]CÓDIGO DE PONTOS'!$A$5:$D$998,4,0)) -> #N/A | C27: =E27*B27 -> #N/A | D27: =IF(A27=0,"",VLOOKUP(A27,'[1]CÓDIGO DE PONTOS'!$A$5:$C$998,3,0)) -> #N/A | E27: =I27 -> 0 | F27: =IF(A27=0,"",VLOOKUP(A27,'[1]CÓDIGO DE PONTOS'!$A$5:$B$998,2,0)) -> #N/A
A28: 200018 | B28: =IF(A28=0,"",VLOOKUP(A28,'[1]CÓDIGO DE PONTOS'!$A$5:$D$998,4,0)) -> #N/A | C28: =E28*B28 -> #N/A | D28: =IF(A28=0,"",VLOOKUP(A28,'[1]CÓDIGO DE PONTOS'!$A$5:$C$998,3,0)) -> #N/A | E28: =I28 -> 0 | F28: =IF(A28=0,"",VLOOKUP(A28,'[1]CÓDIGO DE PONTOS'!$A$5:$B$998,2,0)) -> #N/A
A29: 260282 | B29: =IF(A29=0,"",VLOOKUP(A29,'[1]CÓDIGO DE PONTOS'!$A$5:$D$998,4,0)) -> #N/A | C29: =E29*B29 -> #N/A | D29: =IF(A29=0,"",VLOOKUP(A29,'[1]CÓDIGO DE PONTOS'!$A$5:$C$998,3,0)) -> #N/A | E29: =I29 -> 0 | F29: =IF(A29=0,"",VLOOKUP(A29,'[1]CÓDIGO DE PONTOS'!$A$5:$B$998,2,0)) -> #N/A
A30: 291204 | B30: =IF(A30=0,"",VLOOKUP(A30,'[1]CÓDIGO DE PONTOS'!$A$5:$D$998,4,0)) -> #N/A | C30: =E30*B30 -> #N/A | D30: =IF(A30=0,"",VLOOKUP(A30,'[1]CÓDIGO DE PONTOS'!$A$5:$C$998,3,0)) -> #N/A | E30: =I30 -> 3 | F30: =IF(A30=0,"",VLOOKUP(A30,'[1]CÓDIGO DE PONTOS'!$A$5:$B$998,2,0)) -> #N/A | I30: 3
A31: 291212 | B31: =IF(A31=0,"",VLOOKUP(A31,'[1]CÓDIGO DE PONTOS'!$A$5:$D$998,4,0)) -> #N/A | C31: =E31*B31 -> #N/A | D31: =IF(A31=0,"",VLOOKUP(A31,'[1]CÓDIGO DE PONTOS'!$A$5:$C$998,3,0)) -> #N/A | E31: =I31 -> 0 | F31: =IF(A31=0,"",VLOOKUP(A31,'[1]CÓDIGO DE PONTOS'!$A$5:$B$998,2,0)) -> #N/A
A32: 290963 | B32: =IF(A32=0,"",VLOOKUP(A32,'[1]CÓDIGO DE PONTOS'!$A$5:$D$998,4,0)) -> #N/A | C32: =E32*B32 -> #N/A | D32: =IF(A32=0,"",VLOOKUP(A32,'[1]CÓDIGO DE PONTOS'!$A$5:$C$998,3,0)) -> #N/A | E32: =I32 -> 0 | F32: =IF(A32=0,"",VLOOKUP(A32,'[1]CÓDIGO DE PONTOS'!$A$5:$B$998,2,0)) -> #N/A
A33: 290017 | B33: =IF(A33=0,"",VLOOKUP(A33,'[1]CÓDIGO DE PONTOS'!$A$5:$D$998,4,0)) -> #N/A | C33: =E33*B33 -> #N/A | D33: =IF(A33=0,"",VLOOKUP(A33,'[1]CÓDIGO DE PONTOS'!$A$5:$C$998,3,0)) -> #N/A | E33: =I33 -> 0 | F33: =IF(A33=0,"",VLOOKUP(A33,'[1]CÓDIGO DE PONTOS'!$A$5:$B$998,2,0)) -> #N/A
A34: 450014 | B34: =IF(A34=0,"",VLOOKUP(A34,'[1]CÓDIGO DE PONTOS'!$A$5:$D$998,4,0)) -> #N/A | C34: =E34*B34 -> #N/A | D34: =IF(A34=0,"",VLOOKUP(A34,'[1]CÓDIGO DE PONTOS'!$A$5:$C$998,3,0)) -> #N/A | E34: =I34 -> 0 | F34: =IF(A34=0,"",VLOOKUP(A34,'[1]CÓDIGO DE PONTOS'!$A$5:$B$998,2,0)) -> #N/A
A35: 291229 | B35: =IF(A35=0,"",VLOOKUP(A35,'[1]CÓDIGO DE PONTOS'!$A$5:$D$998,4,0)) -> #N/A | C35: =E35*B35 -> #N/A | D35: =IF(A35=0,"",VLOOKUP(A35,'[1]CÓDIGO DE PONTOS'!$A$5:$C$998,3,0)) -> #N/A | E35: =I35 -> 6 | F35: =IF(A35=0,"",VLOOKUP(A35,'[1]CÓDIGO DE PONTOS'!$A$5:$B$998,2,0)) -> #N/A | I35: 6
A36: 291237 | B36: =IF(A36=0,"",VLOOKUP(A36,'[1]CÓDIGO DE PONTOS'!$A$5:$D$998,4,0)) -> #N/A | C36: =E36*B36 -> #N/A | D36: =IF(A36=0,"",VLOOKUP(A36,'[1]CÓDIGO DE PONTOS'!$A$5:$C$998,3,0)) -> #N/A | E36: =I36 -> 6 | F36: =IF(A36=0,"",VLOOKUP(A36,'[1]CÓDIGO DE PONTOS'!$A$5:$B$998,2,0)) -> #N/A | I36: 6
A37: 290858 | B37: =IF(A37=0,"",VLOOKUP(A37,'[1]CÓDIGO DE PONTOS'!$A$5:$D$998,4,0)) -> #N/A | C37: =E37*B37 -> #N/A | D37: =IF(A37=0,"",VLOOKUP(A37,'[1]CÓDIGO DE PONTOS'!$A$5:$C$998,3,0)) -> #N/A | E37: =I37 -> 0 | F37: =IF(A37=0,"",VLOOKUP(A37,'[1]CÓDIGO DE PONTOS'!$A$5:$B$998,2,0)) -> #N/A
A38: 291245 | B38: =IF(A38=0,"",VLOOKUP(A38,'[1]CÓDIGO DE PONTOS'!$A$5:$D$998,4,0)) -> #N/A | C38: =E38*B38 -> #N/A | D38: =IF(A38=0,"",VLOOKUP(A38,'[1]CÓDIGO DE PONTOS'!$A$5:$C$998,3,0)) -> #N/A | E38: =I38 -> 3 | F38: =IF(A38=0,"",VLOOKUP(A38,'[1]CÓDIGO DE PONTOS'!$A$5:$B$998,2,0)) -> #N/A | I38: 3
A39: 291196 | B39: =IF(A39=0,"",VLOOKUP(A39,'[1]CÓDIGO DE PONTOS'!$A$5:$D$998,4,0)) -> #N/A | C39: =E39*B39 -> #N/A | D39: =IF(A39=0,"",VLOOKUP(A39,'[1]CÓDIGO DE PONTOS'!$A$5:$C$998,3,0)) -> #N/A | E39: =I39 -> 0 | F39: =IF(A39=0,"",VLOOKUP(A39,'[1]CÓDIGO DE PONTOS'!$A$5:$B$998,2,0)) -> #N/A
A40: 290831 | B40: =IF(A40=0,"",VLOOKUP(A40,'[1]CÓDIGO DE PONTOS'!$A$5:$D$998,4,0)) -> #N/A | C40: =E40*B40 -> #N/A | D40: =IF(A40=0,"",VLOOKUP(A40,'[1]CÓDIGO DE PONTOS'!$A$5:$C$998,3,0)) -> #N/A | E40: =I40 -> 18 | F40: =IF(A40=0,"",VLOOKUP(A40,'[1]CÓDIGO DE PONTOS'!$A$5:$B$998,2,0)) -> #N/A | I40: 18
...

Sheet RELATORIO DE MATERIAS
A1: MATERIAIS E EQUIPAMENTOS ENTREGUES PELA TELESP
A4: VAL. UNIT. | B4: CÓD. | C4: QT | D4: DESCRIÇÃO | G4: INSTALAÇÃO | H4: RETIRADA
B5: 0186-0031-0 | D5: DROP OPTICO PRE-C FIG8 COMP OPTITAP 100M
B6: 0186-0034-4 | D6: DROP OPTICO PRE-C FIG8 COMP OPTITAP 220M
B7: 0186-0038-7 | D7: DROP OPTICO PRE-C FIG8 COMP OPTITAP 300M
B8: 0186-0030-1 | D8: DROP OPTICO PRE-C FIG8 COMP OPTITAP 50M
B9: 0186-0033-6 | D9: DROP OPTICO PRE-C FIG8 COMP OPTITAP 150M
B10: 0452-0020-3 | D10: CABO FO CFOA-SM-DD-S-36 - TS
A11: 1137.03 | B11: 0380-8805-3 | C11: 3 | D11: CTOP 8 CABO DROP COM SPLITTER 1:8 | G11: 3
B12: 0219-0028-0 | D12: FIO ESPINAR ISOLADO REFORÇADO FEIR-125MM
B13: 0380-8934-3 | D13: CONECTOR OPT FAC SC/APC DROP FIGB COMPAC
B14: 0258-0163-5 | D14: PONTO TERMINAL DE REDE - OPTICO ( PTR-O )
B15: 0460-0043-7 | D15: KIT DERIVAÇAO ETK MODELO SOFS-12/72FO
B16: 0186-0036-0 | D16: DGOI CONECT MODULAR 144F - PAREDE
B17: 0186-0010-7 | D17: CAIXA DISP PT INT -CDOI-C
B18: 0452-0093-9 | D18: CABO CFOI-BLI-UB 24 LSZH MICROMODULO
B19: 0486-0314-1 | D19: SPLITER OPTICO 1:8 FIBRA NUA/SC-APC
B20: 0256-0321-8 | D20: CEIP- CAIXA DE EMENDA INTERNA DE PARDE 12F
C28: =G28 -> 0
C29: =G29 -> 0
C30: =G30 -> 0 | D30: =IF($N30="","",VLOOKUP(B30,[1]NET!$C$2:$E$512,2,FALSE))
